{"uuid": "a6b6bd38-f1d0-42dc-808f-7aa894927895", "children": ["79ea3a99-6ea8-4851-8895-4556083e8e04", "15d86201-8247-44d4-8e04-a0f69857adb1", "306f1cf9-980b-405a-bedd-d0ffa01ea76b"], "befores": [{"name": "xunit_setup_class_fixture_Test_Search", "status": "broken", "statusDetails": {"message": "selenium.common.exceptions.WebDriverException: Message: An unknown server-side error occurred while processing the command. Original error: Error executing adbExec. Original error: 'Command 'E:\\\\android-sdk-windows\\\\platform-tools\\\\adb.exe -P 5037 -s SLY6R16A12001046 shell ime set io.appium.settings/.UnicodeIME' exited with code 1'; Stderr: 'adb.exe: device 'SLY6R16A12001046' not found'; Code: '1'\n\n", "trace": "  File \"e:\\projects\\python\\po\\venv\\lib\\site-packages\\pluggy\\callers.py\", line 187, in _multicall\n    res = hook_impl.function(*args)\n  File \"e:\\projects\\python\\po\\venv\\lib\\site-packages\\_pytest\\fixtures.py\", line 1126, in pytest_fixture_setup\n    result = call_fixture_func(fixturefunc, request, kwargs)\n  File \"e:\\projects\\python\\po\\venv\\lib\\site-packages\\_pytest\\fixtures.py\", line 925, in call_fixture_func\n    fixture_result = next(generator)\n  File \"e:\\projects\\python\\po\\venv\\lib\\site-packages\\_pytest\\python.py\", line 811, in xunit_setup_class_fixture\n    _call_with_optional_argument(func, self.obj)\n  File \"e:\\projects\\python\\po\\venv\\lib\\site-packages\\_pytest\\python.py\", line 739, in _call_with_optional_argument\n    func(arg)\n  File \"E:\\Projects\\Python\\PO\\Script\\Test_Search.py\", line 18, in setup_class\n    self.driver = init_driver()\n  File \"E:\\Projects\\Python\\PO\\Base\\init_driver.py\", line 21, in init_driver\n    return webdriver.Remote('http://127.0.0.1:4723/wd/hub', desired_caps)\n  File \"e:\\projects\\python\\po\\venv\\lib\\site-packages\\appium\\webdriver\\webdriver.py\", line 156, in __init__\n    super().__init__(\n  File \"e:\\projects\\python\\po\\venv\\lib\\site-packages\\selenium\\webdriver\\remote\\webdriver.py\", line 157, in __init__\n    self.start_session(capabilities, browser_profile)\n  File \"e:\\projects\\python\\po\\venv\\lib\\site-packages\\appium\\webdriver\\webdriver.py\", line 226, in start_session\n    response = self.execute(RemoteCommand.NEW_SESSION, parameters)\n  File \"e:\\projects\\python\\po\\venv\\lib\\site-packages\\selenium\\webdriver\\remote\\webdriver.py\", line 321, in execute\n    self.error_handler.check_response(response)\n  File \"e:\\projects\\python\\po\\venv\\lib\\site-packages\\selenium\\webdriver\\remote\\errorhandler.py\", line 242, in check_response\n    raise exception_class(message, screen, stacktrace)\n"}, "start": 1629896696161, "stop": 1629896699105}], "start": 1629896696161, "stop": 1629896700233}